<?xml version="1.0" ?>
<!-- =================================================================================== -->
<!-- |    This document was autogenerated by xacro from cassie.xacro                   | -->
<!-- |    EDITING THIS FILE BY HAND IS NOT RECOMMENDED                                 | -->
<!-- =================================================================================== -->
<!-- Author: Ross Hartley
	 Email:  rosshart@umich.edu
     Date:   04/24/2016   -->
<robot name="cassie" xmlns:xacro="http://ros.org/wiki/xacro">
  <link name="left_toe">
    <inertial>
      <origin rpy="0 0 0" xyz="-.0059731318780634635318138592197101 .0001 .027218453217757652279340518930439"/>
      <mass value=".15"/>
      <inertia ixx="0.000355372316928377" ixy="0.000079515901654595116769541629508922" ixz="-0.000075421422622665130293048707521564" iyy="0.00038350332171041914570280839669181" iyz="0.000063510617959309273081701385788023" izz="0.000171"/>
      </inertial>
    <visual>
      <origin rpy="0 0 0" xyz="0 0 0"/>
      <geometry>
        <mesh filename="package://cassie_description/meshes/toe.stl" scale="1 1 1"/>
      </geometry>
      <material name="light_grey">
        <color rgba="0.75 0.75 0.75 1"/>
      </material>
    </visual>
  </link>
  <joint name="toe_joint_left" type="continuous">
    <origin rpy="-1.5707963267948966192313216916398 0.69813170079773183076947630739545 3.1415926535897932384626433832795" xyz="-.020049382261784102349233549489327 0 .051305777169056279718439839143684"/>
    <axis xyz="0 0 1"/>
    <parent link="left_toe"/>
    <child link="left_tarsus"/>
    <limit effort="0.9" lower="0.5236" upper="2.4435" velocity="11.5192"/>
  </joint>
  <link name="left_tarsus">
    <inertial>
      <origin rpy="0 0 0" xyz="-.2975 .0094 -0.0013"/>
      <mass value=".782"/>
      <inertia ixx=".00113" ixy="-.00288" ixz="-6.33e-05" iyy=".0231" iyz="3.62e-05" izz=".0239"/>
    </inertial>
    <visual>
      <origin rpy="0 0 0" xyz="0 0 0"/>
      <geometry>
        <mesh filename="package://cassie_description/meshes/tarsus.stl" scale="1 1 1"/>
      </geometry>
      <material name="grey">
        <color rgba="0.35 0.35 0.35 1"/>
      </material>
    </visual>
  </link>
  <joint name="ankle_joint_left" type="continuous">
    <origin rpy="0 0 0" xyz="-.408 .04 0"/>
    <axis xyz="0 0 1"/>
    <parent link="left_tarsus"/>
    <child link="left_shin"/>
    <limit effort="0" lower="-100" upper="100" velocity="100"/>
  </joint>
  <link name="left_shin">
    <inertial>
      <origin rpy="0 0 0" xyz="-.2514 -.0188 0.0002"/>
      <mass value=".577"/>
      <inertia ixx=".000360" ixy=".000334" ixz="-1.94e-07" iyy=".0341" iyz="2.65e-07" izz=".0341"/>
    </inertial>
    <visual>
      <origin rpy="0 0 0" xyz="0 0 0"/>
      <geometry>
        <mesh filename="package://cassie_description/meshes/shin-bone.stl" scale="1 1 1"/>
      </geometry>
      <material name="grey">
        <color rgba="0.35 0.35 0.35 1"/>
      </material>
    </visual>
  </link>
  <joint name="fixed_knee_to_shin_left" type="fixed">
    <origin rpy="0 0 0" xyz="-.4348 -.02 0"/>
    <parent link="left_shin"/>
    <child link="left_knee"/>
  </joint>
  <link name="left_knee">
    <inertial>
      <origin rpy="0 0 0" xyz="-.0377 -.0153 -0.0022"/>
      <mass value=".758"/>
      <inertia ixx=".002160" ixy=".000956" ixz="2.84e-06" iyy=".00144" iyz="7.39e-07" izz=".00334"/>
    </inertial>
    <visual>
      <origin rpy="0 0 0" xyz="0 0 0"/>
      <geometry>
        <mesh filename="package://cassie_description/meshes/knee-output.stl" scale="1 1 1"/>
      </geometry>
      <material name="grey">
        <color rgba="0.35 0.35 0.35 1"/>
      </material>
    </visual>
  </link>
  <joint name="knee_joint_left" type="continuous">
    <origin rpy="0 0 0" xyz="-.0607 -.0474 0"/>
    <axis xyz="0 0 1"/>
    <parent link="left_knee"/>
    <child link="left_thigh"/>
    <limit effort="12.2" lower="0.6458" upper="2.8623" velocity="8.5085"/>
  </joint>
  <link name="left_thigh">
    <inertial>
      <origin rpy="0 0 0" xyz="-.0602 .0001 -.0403"/>
      <mass value="5.52"/>
      <inertia ixx=".018" ixy=".000284" ixz="-0.0117" iyy=".0563" iyz="-1.93e-05" izz=".0498"/>
    </inertial>
    <visual>
      <origin rpy="0 0 0" xyz="0 0 0"/>
      <geometry>
        <mesh filename="package://cassie_description/meshes/thigh.stl" scale="1 1 1"/>
      </geometry>
      <material name="light_grey">
        <color rgba="0.75 0.75 0.75 1"/>
      </material>
    </visual>
  </link>
  <joint name="hip_flexion_left" type="continuous">
    <origin rpy="0 0 0" xyz="-0.12 0 -0.0045"/>
    <axis xyz="0 0 1"/>
    <parent link="left_thigh"/>
    <child link="left_hip"/>
    <limit effort="12.2" lower="-1.3963" upper="0.8727" velocity="8.5085"/>
  </joint>
  <link name="left_hip">
    <inertial>
      <origin rpy="0 0 0" xyz="-.0557 0 0"/>
      <mass value="1.17"/>
      <inertia ixx=".000842" ixy=".000000246" ixz="-.000000625" iyy=".006080" iyz="-.00000004" izz=".006440"/>
    </inertial>
    <visual>
      <origin rpy="0 0 0" xyz="0 0 0"/>
      <geometry>
        <mesh filename="package://cassie_description/meshes/hip.stl" scale="1 1 1"/>
      </geometry>
      <material name="light_grey">
        <color rgba="0.75 0.75 0.75 1"/>
      </material>
    </visual>
  </link>
  <joint name="hip_rotation_left" type="continuous">
    <origin rpy="0 0 0" xyz="0 0 0"/>
    <axis xyz="-1 0 0"/>
    <parent link="left_hip"/>
    <child link="left_pelvis_rotation"/>
    <limit effort="4.5" lower="-0.3927" upper="0.3927" velocity="12.1475"/>
  </joint>
  <link name="left_pelvis_rotation">
    <inertial>
      <origin rpy="0 0 0" xyz="-.1079 .0257 -.0001"/>
      <mass value="1.82"/>
      <inertia ixx=".00559" ixy="-.00000261" ixz="-.000000703" iyy=".00464" iyz=".00000153" izz=".00272"/>
    </inertial>
    <visual>
      <origin rpy="0 0 0" xyz="0 0 0"/>
      <geometry>
        <mesh filename="package://cassie_description/meshes/yaw.stl" scale="1 1 1"/>
      </geometry>
      <material name="light_grey">
        <color rgba="0.75 0.75 0.75 1"/>
      </material>
    </visual>
  </link>
  <joint name="hip_abduction_left" type="continuous">
    <origin rpy="-1.5707963267948966192313216916398 0 1.5707963267948966192313216916398" xyz="-0.09 0 0"/>
    <axis xyz="1 0 0"/>
    <parent link="left_pelvis_rotation"/>
    <child link="left_pelvis_abduction"/>
    <limit effort="4.5" lower="-0.3927" upper="0.2618" velocity="12.1475"/>
  </joint>
  <link name="left_pelvis_abduction">
    <inertial>
      <origin rpy="0 0 0" xyz="0 0 0"/>
      <mass value="0"/>
      <inertia ixx="0" ixy="0" ixz="0" iyy="0" iyz="0" izz="0"/>
    </inertial>
    <visual>
      <origin rpy="0 0 0" xyz="0 0 0"/>
      <geometry>
        <mesh filename="package://cassie_description/meshes/abduction.stl" scale="1 1 1"/>
      </geometry>
      <material name="light_grey">
        <color rgba="0.75 0.75 0.75 1"/>
      </material>
    </visual>
  </link>
  <joint name="fixed_left" type="fixed">
    <origin rpy="0 1.5707963267948966192313216916398 0" xyz="0.07 0 0"/>
    <parent link="left_pelvis_abduction"/>
    <child link="pelvis"/>
  </joint>
  <link name="pelvis">
    <inertial>
      <origin rpy="0 0 0" xyz="-.0284 -.1350 .0297"/>
      <mass value="10.33"/>
      <inertia ixx=".113" ixy="-.000516" ixz="-.015" iyy=".084" iyz="-.000169" izz=".0942"/> <!--<inertia ixx=".0942" ixy=".000169" ixz=".015" iyy=".084" iyz=".000516" izz=".113"/>-->
    </inertial>
    <visual>
      <origin rpy="0 0 0" xyz="0 0 0"/>
      <geometry>
        <mesh filename="package://cassie_description/meshes/pelvis.stl" scale="1 1 1"/>
      </geometry>
      <material name="grey">
        <color rgba="0.35 0.35 0.35 1"/>
      </material>
    </visual>
  </link>
  
  <joint name="fixed_right" type="fixed">
    <origin rpy="0 0 0" xyz="0 -0.27 0"/>
    <parent link="pelvis"/>
    <child link="right_pelvis_abduction"/>
  </joint>
  <link name="right_pelvis_abduction">
    <inertial>
      <origin rpy="0 0 0" xyz="0 0 0"/>
      <mass value="0"/>
      <inertia ixx="0" ixy="0" ixz="0" iyy="0" iyz="0" izz="0"/>
    </inertial>
    <visual>
      <origin rpy="0 0 0" xyz="0 0 0"/>
      <geometry>
        <mesh filename="package://cassie_description/meshes/abduction_mirror.stl" scale="1 1 1"/>
      </geometry>
      <material name="light_grey">
        <color rgba="0.75 0.75 0.75 1"/>
      </material>
    </visual>
  </link>
  <joint name="hip_abduction_right" type="continuous">
    <origin rpy="0 -1.57079632679 0" xyz="0 0 -0.07"/>
    <axis xyz="1 0 0"/>
    <parent link="right_pelvis_abduction"/>
    <child link="right_pelvis_rotation"/>
    <limit effort="4.5" lower="-0.3927" upper="0.2618" velocity="12.1475"/>
  </joint>
  <link name="right_pelvis_rotation">
    <inertial>
      <origin rpy="0 0 0" xyz=".0257 -0.0001 .0179"/>
      <mass value="1.82"/>
      <inertia ixx=".00272" ixy="-7.03e-07" ixz=".00000153" iyy=".00559" iyz="-2.61e-06" izz=".004640"/>
    </inertial>
    <visual>
      <origin rpy="0 0 0" xyz="0 0 0"/>
      <geometry>
        <mesh filename="package://cassie_description/meshes/yaw_mirror.stl" scale="1 1 1"/>
      </geometry>
      <material name="light_grey">
        <color rgba="0.75 0.75 0.75 1"/>
      </material>
    </visual>
  </link>
  <joint name="hip_rotation_right" type="continuous">
    <origin rpy="0 1.57079632679 -1.57079632679" xyz="0 0 -0.09"/>
    <axis xyz="-1 0 0"/>
    <parent link="right_pelvis_rotation"/>
    <child link="right_hip"/>
    <limit effort="4.5" lower="-0.3927" upper="0.3927" velocity="12.1475"/>
  </joint>
  <link name="right_hip">
    <inertial>
      <origin rpy="0 0 0" xyz="-.0557 0 0"/>
      <mass value="1.17"/>
      <inertia ixx=".000842" ixy=".000000246" ixz="-.000000625" iyy=".006080" iyz="-.00000004" izz=".006440"/>
    </inertial>
    <visual>
      <origin rpy="0 0 0" xyz="0 0 0"/>
      <geometry>
        <mesh filename="package://cassie_description/meshes/hip_mirror.stl" scale="1 1 1"/>
      </geometry>
      <material name="light_grey">
        <color rgba="0.75 0.75 0.75 1"/>
      </material>
    </visual>
  </link>
  <joint name="hip_flexion_right" type="continuous">
    <origin rpy="0 0 0" xyz="0 0 0"/>
    <axis xyz="0 0 1"/>
    <parent link="right_hip"/>
    <child link="right_thigh"/>
    <limit effort="12.2" lower="-0.8727" upper="1.3963" velocity="8.5085"/>
  </joint>
  <link name="right_thigh">
    <inertial>
      <origin rpy="0 0 0" xyz=".0598 .0001 0.0358"/>
      <mass value="5.52"/>
      <inertia ixx=".018" ixy=".000284" ixz="0.0117" iyy=".0563" iyz="1.93e-05" izz=".0498"/>
    </inertial>
    <visual>
      <origin rpy="0 0 0" xyz="0 0 0"/>
      <geometry>
        <mesh filename="package://cassie_description/meshes/thigh_mirror.stl" scale="1 1 1"/>
      </geometry>
      <material name="light_grey">
        <color rgba="0.75 0.75 0.75 1"/>
      </material>
    </visual>
  </link>
  <joint name="knee_joint_right" type="continuous">
    <origin rpy="0 0 0" xyz="0.12 0 -0.0045"/>
    <axis xyz="0 0 1"/>
    <parent link="right_thigh"/>
    <child link="right_knee"/>
    <limit effort="12.2" lower="-2.8623" upper="-0.6458" velocity="8.5085"/>
  </joint>
  <link name="right_knee">
    <inertial>
      <origin rpy="0 0 0" xyz=".023 .0321 0.0022"/>
      <mass value=".758"/>
      <inertia ixx=".002160" ixy=".000956" ixz="-2.84e-06" iyy=".00144" iyz="-7.39e-07" izz=".00334"/>
    </inertial>
    <visual>
      <origin rpy="0 0 0" xyz="0 0 0"/>
      <geometry>
        <mesh filename="package://cassie_description/meshes/knee-output_mirror.stl" scale="1 1 1"/>
      </geometry>
      <material name="grey">
        <color rgba="0.35 0.35 0.35 1"/>
      </material>
    </visual>
  </link>
  <joint name="fixed_knee_to_shin_right" type="fixed">
    <origin rpy="0 0 0" xyz="0.0607 0.0474 0"/>
    <parent link="right_knee"/>
    <child link="right_shin"/>
  </joint>
  <link name="right_shin">
    <inertial>
      <origin rpy="0 0 0" xyz=".1834 .0012 -0.0002"/>
      <mass value=".577"/>
      <inertia ixx=".000360" ixy=".000334" ixz="1.94e-07" iyy=".0341" iyz="-2.65e-07" izz=".0341"/>
    </inertial>
    <visual>
      <origin rpy="0 0 0" xyz="0 0 0"/>
      <geometry>
        <mesh filename="package://cassie_description/meshes/shin-bone_mirror.stl" scale="1 1 1"/>
      </geometry>
      <material name="grey">
        <color rgba="0.35 0.35 0.35 1"/>
      </material>
    </visual>
  </link>
  <joint name="ankle_joint_right" type="continuous">
    <origin rpy="0 0 0" xyz="0.4348 0.02 0"/>
    <axis xyz="0 0 1"/>
    <parent link="right_shin"/>
    <child link="right_tarsus"/>
    <limit effort="0" lower="-100" upper="100" velocity="100"/>
  </joint>
  <link name="right_tarsus">
    <inertial>
      <origin rpy="0 0 0" xyz=".1105 -.0306 0.0013"/>
      <mass value=".782"/>
      <inertia ixx=".00113" ixy="-.00288" ixz="6.33e-05" iyy=".0231" iyz="-3.62e-05" izz=".0239"/>
    </inertial>
    <visual>
      <origin rpy="0 0 0" xyz="0 0 0"/>
      <geometry>
        <mesh filename="package://cassie_description/meshes/tarsus_mirror.stl" scale="1 1 1"/>
      </geometry>
      <material name="grey">
        <color rgba="0.35 0.35 0.35 1"/>
      </material>
    </visual>
  </link>
  
  <joint name="toe_joint_right" type="continuous">
    <origin rpy="0 0 0" xyz="0.408 -0.04 0"/>
    <axis xyz="0 0 1"/>
    <parent link="right_tarsus"/>
    <child link="right_toe"/>
    <limit effort="0.9" lower="-2.4435" upper="-0.5236" velocity="11.5192"/>
  </joint>
  <link name="right_toe">
    <inertial>
      <origin rpy="0 0 0" xyz=".0047 .0275 0.0001"/>
      <mass value=".15"/>
      <inertia ixx=".000287" ixy="-.0000986" ixz="1.46e-06" iyy=".000171" iyz="-1.72e-07" izz=".000449"/>
    </inertial>
    <visual>
      <origin rpy="0 0 0" xyz="0 0 0"/>
      <geometry>
        <mesh filename="package://cassie_description/meshes/toe_mirror.stl" scale="1 1 1"/>
      </geometry>
      <material name="light_grey">
        <color rgba="0.75 0.75 0.75 1"/>
      </material>
    </visual>
  </link>
  <!--
  -->
  <transmission name="toe_joint_trans_left" type="transmission_interface/SimpleTransmission">
    <joint name="toe_joint_left"/>
    <actuator name="toe_joint_motor_left"/>
    <motorInertia>0.0000049</motorInertia>
    <mechanicalReduction>50</mechanicalReduction>
  </transmission>
  <transmission name="knee_joint_trans_left" type="transmission_interface/SimpleTransmission">
    <joint name="knee_joint_left"/>
    <actuator name="knee_joint_motor_left"/>
    <motorInertia>0.000365</motorInertia>
    <mechanicalReduction>16</mechanicalReduction>
  </transmission>
  <transmission name="hip_flexion_trans_left" type="transmission_interface/SimpleTransmission">
    <joint name="hip_flexion_left"/>
    <actuator name="hip_flexion_motor_left"/>
    <motorInertia>0.000365</motorInertia>
    <mechanicalReduction>16</mechanicalReduction>
  </transmission>
  <transmission name="hip_rotation_trans_left" type="transmission_interface/SimpleTransmission">
    <joint name="hip_rotation_left"/>
    <actuator name="hip_rotation_motor_left"/>
    <motorInertia>0.000061</motorInertia>
    <mechanicalReduction>25</mechanicalReduction>
  </transmission>
  <transmission name="hip_abduction_trans_left" type="transmission_interface/SimpleTransmission">
    <joint name="hip_abduction_left"/>
    <actuator name="hip_abduction_motor_left"/>
    <motorInertia>0.000061</motorInertia>
    <mechanicalReduction>25</mechanicalReduction>
  </transmission>
  <transmission name="hip_abduction_trans_right" type="transmission_interface/SimpleTransmission">
    <joint name="hip_abduction_right"/>
    <actuator name="hip_abduction_motor_right"/>
    <motorInertia>0.000061</motorInertia>
    <mechanicalReduction>25</mechanicalReduction>
  </transmission>
  <transmission name="hip_rotation_trans_right" type="transmission_interface/SimpleTransmission">
    <joint name="hip_rotation_right"/>
    <actuator name="hip_rotation_motor_right"/>
    <motorInertia>0.000061</motorInertia>
    <mechanicalReduction>25</mechanicalReduction>
  </transmission>
  <transmission name="hip_flexion_trans_right" type="transmission_interface/SimpleTransmission">
    <joint name="hip_flexion_right"/>
    <actuator name="hip_flexion_motor_right"/>
    <motorInertia>0.000365</motorInertia>
    <mechanicalReduction>16</mechanicalReduction>
  </transmission>
  <transmission name="knee_joint_trans_right" type="transmission_interface/SimpleTransmission">
    <joint name="knee_joint_right"/>
    <actuator name="knee_joint_motor_right"/>
    <motorInertia>0.000365</motorInertia>
    <mechanicalReduction>16</mechanicalReduction>
  </transmission>
  
  <transmission name="toe_joint_trans_right" type="transmission_interface/SimpleTransmission">
    <joint name="toe_joint_right"/>
    <actuator name="toe_joint_motor_right"/>
    <motorInertia>0.0000049</motorInertia>
    <mechanicalReduction>50</mechanicalReduction>
  </transmission>
  <!--
  -->
</robot>
